{
 "cells": [
  {
   "cell_type": "code",
   "execution_count": 6,
   "metadata": {},
   "outputs": [],
   "source": [
    "#importing api key from .env folder \n",
    "import os\n",
    "from dotenv import load_dotenv\n",
    "from openai import OpenAI\n",
    "load_dotenv()\n",
    "api_key  = os.getenv('OPENAI_API_KEY')\n"
   ]
  },
  {
   "cell_type": "code",
   "execution_count": 2,
   "metadata": {},
   "outputs": [
    {
     "name": "stdout",
     "output_type": "stream",
     "text": [
      "https://oaidalleapiprodscus.blob.core.windows.net/private/org-57DHbubaUsKcpEwBCHTVrS6b/user-ZPTxrE5Z3of20YjzdGT5LsFj/img-o033QAHHhK7D76McIhX05Dnt.png?st=2024-01-10T19%3A43%3A20Z&se=2024-01-10T21%3A43%3A20Z&sp=r&sv=2021-08-06&sr=b&rscd=inline&rsct=image/png&skoid=6aaadede-4fb3-4698-a8f6-684d7786b067&sktid=a48cca56-e6da-484e-a814-9c849652bcb3&skt=2024-01-10T02%3A17%3A20Z&ske=2024-01-11T02%3A17%3A20Z&sks=b&skv=2021-08-06&sig=OUcmsOQD6SYt7pODd8BisWcyTNVd4hRgKNZ/2kvgaMg%3D\n"
     ]
    }
   ],
   "source": [
    "from dotenv import load_dotenv, find_dotenv\n",
    "import os\n",
    "from openai import OpenAI\n",
    "from PIL import Image, ImageDraw, ImageFont\n",
    "import requests\n",
    "from io import BytesIO\n",
    "\n",
    "# api key is already called above \n",
    "client = OpenAI(api_key=api_key)\n",
    "\n",
    "response = client.images.generate(\n",
    "    model=\"dall-e-3\",\n",
    "  \n",
    "    #logo_image = Image.open(\"/home/hp/Documents/week 5/End-to-End-web3-dapps-certifcate-generation/certificate_image/logo.jpg\"),\n",
    "    prompt='completion of certificate + white background + red logo of 10 academy + have space for name and date of competion, try to make it formal + show the certeficate fully + no other images + landscape view',\n",
    "    size=\"1024x1024\",\n",
    "    quality=\"standard\",\n",
    "    n=1,\n",
    ")\n",
    "\n",
    "image_url = response.data[0].url\n",
    "\n",
    "print(image_url)"
   ]
  },
  {
   "cell_type": "code",
   "execution_count": 4,
   "metadata": {},
   "outputs": [
    {
     "ename": "ConnectionError",
     "evalue": "HTTPSConnectionPool(host='oaidalleapiprodscus.blob.core.windows.net', port=443): Max retries exceeded with url: /private/org-57DHbubaUsKcpEwBCHTVrS6b/user-ZPTxrE5Z3of20YjzdGT5LsFj/img-o033QAHHhK7D76McIhX05Dnt.png?st=2024-01-10T19%3A43%3A20Z&se=2024-01-10T21%3A43%3A20Z&sp=r&sv=2021-08-06&sr=b&rscd=inline&rsct=image/png&skoid=6aaadede-4fb3-4698-a8f6-684d7786b067&sktid=a48cca56-e6da-484e-a814-9c849652bcb3&skt=2024-01-10T02%3A17%3A20Z&ske=2024-01-11T02%3A17%3A20Z&sks=b&skv=2021-08-06&sig=OUcmsOQD6SYt7pODd8BisWcyTNVd4hRgKNZ/2kvgaMg%3D (Caused by NewConnectionError('<urllib3.connection.HTTPSConnection object at 0x7fd02ff4b790>: Failed to establish a new connection: [Errno -2] Name or service not known'))",
     "output_type": "error",
     "traceback": [
      "\u001b[0;31m---------------------------------------------------------------------------\u001b[0m",
      "\u001b[0;31mgaierror\u001b[0m                                  Traceback (most recent call last)",
      "File \u001b[0;32m~/.local/lib/python3.10/site-packages/urllib3/connection.py:174\u001b[0m, in \u001b[0;36mHTTPConnection._new_conn\u001b[0;34m(self)\u001b[0m\n\u001b[1;32m    173\u001b[0m \u001b[38;5;28;01mtry\u001b[39;00m:\n\u001b[0;32m--> 174\u001b[0m     conn \u001b[38;5;241m=\u001b[39m \u001b[43mconnection\u001b[49m\u001b[38;5;241;43m.\u001b[39;49m\u001b[43mcreate_connection\u001b[49m\u001b[43m(\u001b[49m\n\u001b[1;32m    175\u001b[0m \u001b[43m        \u001b[49m\u001b[43m(\u001b[49m\u001b[38;5;28;43mself\u001b[39;49m\u001b[38;5;241;43m.\u001b[39;49m\u001b[43m_dns_host\u001b[49m\u001b[43m,\u001b[49m\u001b[43m \u001b[49m\u001b[38;5;28;43mself\u001b[39;49m\u001b[38;5;241;43m.\u001b[39;49m\u001b[43mport\u001b[49m\u001b[43m)\u001b[49m\u001b[43m,\u001b[49m\u001b[43m \u001b[49m\u001b[38;5;28;43mself\u001b[39;49m\u001b[38;5;241;43m.\u001b[39;49m\u001b[43mtimeout\u001b[49m\u001b[43m,\u001b[49m\u001b[43m \u001b[49m\u001b[38;5;241;43m*\u001b[39;49m\u001b[38;5;241;43m*\u001b[39;49m\u001b[43mextra_kw\u001b[49m\n\u001b[1;32m    176\u001b[0m \u001b[43m    \u001b[49m\u001b[43m)\u001b[49m\n\u001b[1;32m    178\u001b[0m \u001b[38;5;28;01mexcept\u001b[39;00m SocketTimeout:\n",
      "File \u001b[0;32m~/.local/lib/python3.10/site-packages/urllib3/util/connection.py:72\u001b[0m, in \u001b[0;36mcreate_connection\u001b[0;34m(address, timeout, source_address, socket_options)\u001b[0m\n\u001b[1;32m     68\u001b[0m     \u001b[38;5;28;01mreturn\u001b[39;00m six\u001b[38;5;241m.\u001b[39mraise_from(\n\u001b[1;32m     69\u001b[0m         LocationParseError(\u001b[38;5;124mu\u001b[39m\u001b[38;5;124m\"\u001b[39m\u001b[38;5;124m'\u001b[39m\u001b[38;5;132;01m%s\u001b[39;00m\u001b[38;5;124m'\u001b[39m\u001b[38;5;124m, label empty or too long\u001b[39m\u001b[38;5;124m\"\u001b[39m \u001b[38;5;241m%\u001b[39m host), \u001b[38;5;28;01mNone\u001b[39;00m\n\u001b[1;32m     70\u001b[0m     )\n\u001b[0;32m---> 72\u001b[0m \u001b[38;5;28;01mfor\u001b[39;00m res \u001b[38;5;129;01min\u001b[39;00m \u001b[43msocket\u001b[49m\u001b[38;5;241;43m.\u001b[39;49m\u001b[43mgetaddrinfo\u001b[49m\u001b[43m(\u001b[49m\u001b[43mhost\u001b[49m\u001b[43m,\u001b[49m\u001b[43m \u001b[49m\u001b[43mport\u001b[49m\u001b[43m,\u001b[49m\u001b[43m \u001b[49m\u001b[43mfamily\u001b[49m\u001b[43m,\u001b[49m\u001b[43m \u001b[49m\u001b[43msocket\u001b[49m\u001b[38;5;241;43m.\u001b[39;49m\u001b[43mSOCK_STREAM\u001b[49m\u001b[43m)\u001b[49m:\n\u001b[1;32m     73\u001b[0m     af, socktype, proto, canonname, sa \u001b[38;5;241m=\u001b[39m res\n",
      "File \u001b[0;32m/usr/lib/python3.10/socket.py:955\u001b[0m, in \u001b[0;36mgetaddrinfo\u001b[0;34m(host, port, family, type, proto, flags)\u001b[0m\n\u001b[1;32m    954\u001b[0m addrlist \u001b[38;5;241m=\u001b[39m []\n\u001b[0;32m--> 955\u001b[0m \u001b[38;5;28;01mfor\u001b[39;00m res \u001b[38;5;129;01min\u001b[39;00m \u001b[43m_socket\u001b[49m\u001b[38;5;241;43m.\u001b[39;49m\u001b[43mgetaddrinfo\u001b[49m\u001b[43m(\u001b[49m\u001b[43mhost\u001b[49m\u001b[43m,\u001b[49m\u001b[43m \u001b[49m\u001b[43mport\u001b[49m\u001b[43m,\u001b[49m\u001b[43m \u001b[49m\u001b[43mfamily\u001b[49m\u001b[43m,\u001b[49m\u001b[43m \u001b[49m\u001b[38;5;28;43mtype\u001b[39;49m\u001b[43m,\u001b[49m\u001b[43m \u001b[49m\u001b[43mproto\u001b[49m\u001b[43m,\u001b[49m\u001b[43m \u001b[49m\u001b[43mflags\u001b[49m\u001b[43m)\u001b[49m:\n\u001b[1;32m    956\u001b[0m     af, socktype, proto, canonname, sa \u001b[38;5;241m=\u001b[39m res\n",
      "\u001b[0;31mgaierror\u001b[0m: [Errno -2] Name or service not known",
      "\nDuring handling of the above exception, another exception occurred:\n",
      "\u001b[0;31mNewConnectionError\u001b[0m                        Traceback (most recent call last)",
      "File \u001b[0;32m~/.local/lib/python3.10/site-packages/urllib3/connectionpool.py:715\u001b[0m, in \u001b[0;36mHTTPConnectionPool.urlopen\u001b[0;34m(self, method, url, body, headers, retries, redirect, assert_same_host, timeout, pool_timeout, release_conn, chunked, body_pos, **response_kw)\u001b[0m\n\u001b[1;32m    714\u001b[0m \u001b[38;5;66;03m# Make the request on the httplib connection object.\u001b[39;00m\n\u001b[0;32m--> 715\u001b[0m httplib_response \u001b[38;5;241m=\u001b[39m \u001b[38;5;28;43mself\u001b[39;49m\u001b[38;5;241;43m.\u001b[39;49m\u001b[43m_make_request\u001b[49m\u001b[43m(\u001b[49m\n\u001b[1;32m    716\u001b[0m \u001b[43m    \u001b[49m\u001b[43mconn\u001b[49m\u001b[43m,\u001b[49m\n\u001b[1;32m    717\u001b[0m \u001b[43m    \u001b[49m\u001b[43mmethod\u001b[49m\u001b[43m,\u001b[49m\n\u001b[1;32m    718\u001b[0m \u001b[43m    \u001b[49m\u001b[43murl\u001b[49m\u001b[43m,\u001b[49m\n\u001b[1;32m    719\u001b[0m \u001b[43m    \u001b[49m\u001b[43mtimeout\u001b[49m\u001b[38;5;241;43m=\u001b[39;49m\u001b[43mtimeout_obj\u001b[49m\u001b[43m,\u001b[49m\n\u001b[1;32m    720\u001b[0m \u001b[43m    \u001b[49m\u001b[43mbody\u001b[49m\u001b[38;5;241;43m=\u001b[39;49m\u001b[43mbody\u001b[49m\u001b[43m,\u001b[49m\n\u001b[1;32m    721\u001b[0m \u001b[43m    \u001b[49m\u001b[43mheaders\u001b[49m\u001b[38;5;241;43m=\u001b[39;49m\u001b[43mheaders\u001b[49m\u001b[43m,\u001b[49m\n\u001b[1;32m    722\u001b[0m \u001b[43m    \u001b[49m\u001b[43mchunked\u001b[49m\u001b[38;5;241;43m=\u001b[39;49m\u001b[43mchunked\u001b[49m\u001b[43m,\u001b[49m\n\u001b[1;32m    723\u001b[0m \u001b[43m\u001b[49m\u001b[43m)\u001b[49m\n\u001b[1;32m    725\u001b[0m \u001b[38;5;66;03m# If we're going to release the connection in ``finally:``, then\u001b[39;00m\n\u001b[1;32m    726\u001b[0m \u001b[38;5;66;03m# the response doesn't need to know about the connection. Otherwise\u001b[39;00m\n\u001b[1;32m    727\u001b[0m \u001b[38;5;66;03m# it will also try to release it and we'll have a double-release\u001b[39;00m\n\u001b[1;32m    728\u001b[0m \u001b[38;5;66;03m# mess.\u001b[39;00m\n",
      "File \u001b[0;32m~/.local/lib/python3.10/site-packages/urllib3/connectionpool.py:404\u001b[0m, in \u001b[0;36mHTTPConnectionPool._make_request\u001b[0;34m(self, conn, method, url, timeout, chunked, **httplib_request_kw)\u001b[0m\n\u001b[1;32m    403\u001b[0m \u001b[38;5;28;01mtry\u001b[39;00m:\n\u001b[0;32m--> 404\u001b[0m     \u001b[38;5;28;43mself\u001b[39;49m\u001b[38;5;241;43m.\u001b[39;49m\u001b[43m_validate_conn\u001b[49m\u001b[43m(\u001b[49m\u001b[43mconn\u001b[49m\u001b[43m)\u001b[49m\n\u001b[1;32m    405\u001b[0m \u001b[38;5;28;01mexcept\u001b[39;00m (SocketTimeout, BaseSSLError) \u001b[38;5;28;01mas\u001b[39;00m e:\n\u001b[1;32m    406\u001b[0m     \u001b[38;5;66;03m# Py2 raises this as a BaseSSLError, Py3 raises it as socket timeout.\u001b[39;00m\n",
      "File \u001b[0;32m~/.local/lib/python3.10/site-packages/urllib3/connectionpool.py:1058\u001b[0m, in \u001b[0;36mHTTPSConnectionPool._validate_conn\u001b[0;34m(self, conn)\u001b[0m\n\u001b[1;32m   1057\u001b[0m \u001b[38;5;28;01mif\u001b[39;00m \u001b[38;5;129;01mnot\u001b[39;00m \u001b[38;5;28mgetattr\u001b[39m(conn, \u001b[38;5;124m\"\u001b[39m\u001b[38;5;124msock\u001b[39m\u001b[38;5;124m\"\u001b[39m, \u001b[38;5;28;01mNone\u001b[39;00m):  \u001b[38;5;66;03m# AppEngine might not have  `.sock`\u001b[39;00m\n\u001b[0;32m-> 1058\u001b[0m     \u001b[43mconn\u001b[49m\u001b[38;5;241;43m.\u001b[39;49m\u001b[43mconnect\u001b[49m\u001b[43m(\u001b[49m\u001b[43m)\u001b[49m\n\u001b[1;32m   1060\u001b[0m \u001b[38;5;28;01mif\u001b[39;00m \u001b[38;5;129;01mnot\u001b[39;00m conn\u001b[38;5;241m.\u001b[39mis_verified:\n",
      "File \u001b[0;32m~/.local/lib/python3.10/site-packages/urllib3/connection.py:363\u001b[0m, in \u001b[0;36mHTTPSConnection.connect\u001b[0;34m(self)\u001b[0m\n\u001b[1;32m    361\u001b[0m \u001b[38;5;28;01mdef\u001b[39;00m \u001b[38;5;21mconnect\u001b[39m(\u001b[38;5;28mself\u001b[39m):\n\u001b[1;32m    362\u001b[0m     \u001b[38;5;66;03m# Add certificate verification\u001b[39;00m\n\u001b[0;32m--> 363\u001b[0m     \u001b[38;5;28mself\u001b[39m\u001b[38;5;241m.\u001b[39msock \u001b[38;5;241m=\u001b[39m conn \u001b[38;5;241m=\u001b[39m \u001b[38;5;28;43mself\u001b[39;49m\u001b[38;5;241;43m.\u001b[39;49m\u001b[43m_new_conn\u001b[49m\u001b[43m(\u001b[49m\u001b[43m)\u001b[49m\n\u001b[1;32m    364\u001b[0m     hostname \u001b[38;5;241m=\u001b[39m \u001b[38;5;28mself\u001b[39m\u001b[38;5;241m.\u001b[39mhost\n",
      "File \u001b[0;32m~/.local/lib/python3.10/site-packages/urllib3/connection.py:186\u001b[0m, in \u001b[0;36mHTTPConnection._new_conn\u001b[0;34m(self)\u001b[0m\n\u001b[1;32m    185\u001b[0m \u001b[38;5;28;01mexcept\u001b[39;00m SocketError \u001b[38;5;28;01mas\u001b[39;00m e:\n\u001b[0;32m--> 186\u001b[0m     \u001b[38;5;28;01mraise\u001b[39;00m NewConnectionError(\n\u001b[1;32m    187\u001b[0m         \u001b[38;5;28mself\u001b[39m, \u001b[38;5;124m\"\u001b[39m\u001b[38;5;124mFailed to establish a new connection: \u001b[39m\u001b[38;5;132;01m%s\u001b[39;00m\u001b[38;5;124m\"\u001b[39m \u001b[38;5;241m%\u001b[39m e\n\u001b[1;32m    188\u001b[0m     )\n\u001b[1;32m    190\u001b[0m \u001b[38;5;28;01mreturn\u001b[39;00m conn\n",
      "\u001b[0;31mNewConnectionError\u001b[0m: <urllib3.connection.HTTPSConnection object at 0x7fd02ff4b790>: Failed to establish a new connection: [Errno -2] Name or service not known",
      "\nDuring handling of the above exception, another exception occurred:\n",
      "\u001b[0;31mMaxRetryError\u001b[0m                             Traceback (most recent call last)",
      "File \u001b[0;32m~/.local/lib/python3.10/site-packages/requests/adapters.py:486\u001b[0m, in \u001b[0;36mHTTPAdapter.send\u001b[0;34m(self, request, stream, timeout, verify, cert, proxies)\u001b[0m\n\u001b[1;32m    485\u001b[0m \u001b[38;5;28;01mtry\u001b[39;00m:\n\u001b[0;32m--> 486\u001b[0m     resp \u001b[38;5;241m=\u001b[39m \u001b[43mconn\u001b[49m\u001b[38;5;241;43m.\u001b[39;49m\u001b[43murlopen\u001b[49m\u001b[43m(\u001b[49m\n\u001b[1;32m    487\u001b[0m \u001b[43m        \u001b[49m\u001b[43mmethod\u001b[49m\u001b[38;5;241;43m=\u001b[39;49m\u001b[43mrequest\u001b[49m\u001b[38;5;241;43m.\u001b[39;49m\u001b[43mmethod\u001b[49m\u001b[43m,\u001b[49m\n\u001b[1;32m    488\u001b[0m \u001b[43m        \u001b[49m\u001b[43murl\u001b[49m\u001b[38;5;241;43m=\u001b[39;49m\u001b[43murl\u001b[49m\u001b[43m,\u001b[49m\n\u001b[1;32m    489\u001b[0m \u001b[43m        \u001b[49m\u001b[43mbody\u001b[49m\u001b[38;5;241;43m=\u001b[39;49m\u001b[43mrequest\u001b[49m\u001b[38;5;241;43m.\u001b[39;49m\u001b[43mbody\u001b[49m\u001b[43m,\u001b[49m\n\u001b[1;32m    490\u001b[0m \u001b[43m        \u001b[49m\u001b[43mheaders\u001b[49m\u001b[38;5;241;43m=\u001b[39;49m\u001b[43mrequest\u001b[49m\u001b[38;5;241;43m.\u001b[39;49m\u001b[43mheaders\u001b[49m\u001b[43m,\u001b[49m\n\u001b[1;32m    491\u001b[0m \u001b[43m        \u001b[49m\u001b[43mredirect\u001b[49m\u001b[38;5;241;43m=\u001b[39;49m\u001b[38;5;28;43;01mFalse\u001b[39;49;00m\u001b[43m,\u001b[49m\n\u001b[1;32m    492\u001b[0m \u001b[43m        \u001b[49m\u001b[43massert_same_host\u001b[49m\u001b[38;5;241;43m=\u001b[39;49m\u001b[38;5;28;43;01mFalse\u001b[39;49;00m\u001b[43m,\u001b[49m\n\u001b[1;32m    493\u001b[0m \u001b[43m        \u001b[49m\u001b[43mpreload_content\u001b[49m\u001b[38;5;241;43m=\u001b[39;49m\u001b[38;5;28;43;01mFalse\u001b[39;49;00m\u001b[43m,\u001b[49m\n\u001b[1;32m    494\u001b[0m \u001b[43m        \u001b[49m\u001b[43mdecode_content\u001b[49m\u001b[38;5;241;43m=\u001b[39;49m\u001b[38;5;28;43;01mFalse\u001b[39;49;00m\u001b[43m,\u001b[49m\n\u001b[1;32m    495\u001b[0m \u001b[43m        \u001b[49m\u001b[43mretries\u001b[49m\u001b[38;5;241;43m=\u001b[39;49m\u001b[38;5;28;43mself\u001b[39;49m\u001b[38;5;241;43m.\u001b[39;49m\u001b[43mmax_retries\u001b[49m\u001b[43m,\u001b[49m\n\u001b[1;32m    496\u001b[0m \u001b[43m        \u001b[49m\u001b[43mtimeout\u001b[49m\u001b[38;5;241;43m=\u001b[39;49m\u001b[43mtimeout\u001b[49m\u001b[43m,\u001b[49m\n\u001b[1;32m    497\u001b[0m \u001b[43m        \u001b[49m\u001b[43mchunked\u001b[49m\u001b[38;5;241;43m=\u001b[39;49m\u001b[43mchunked\u001b[49m\u001b[43m,\u001b[49m\n\u001b[1;32m    498\u001b[0m \u001b[43m    \u001b[49m\u001b[43m)\u001b[49m\n\u001b[1;32m    500\u001b[0m \u001b[38;5;28;01mexcept\u001b[39;00m (ProtocolError, \u001b[38;5;167;01mOSError\u001b[39;00m) \u001b[38;5;28;01mas\u001b[39;00m err:\n",
      "File \u001b[0;32m~/.local/lib/python3.10/site-packages/urllib3/connectionpool.py:799\u001b[0m, in \u001b[0;36mHTTPConnectionPool.urlopen\u001b[0;34m(self, method, url, body, headers, retries, redirect, assert_same_host, timeout, pool_timeout, release_conn, chunked, body_pos, **response_kw)\u001b[0m\n\u001b[1;32m    797\u001b[0m     e \u001b[38;5;241m=\u001b[39m ProtocolError(\u001b[38;5;124m\"\u001b[39m\u001b[38;5;124mConnection aborted.\u001b[39m\u001b[38;5;124m\"\u001b[39m, e)\n\u001b[0;32m--> 799\u001b[0m retries \u001b[38;5;241m=\u001b[39m \u001b[43mretries\u001b[49m\u001b[38;5;241;43m.\u001b[39;49m\u001b[43mincrement\u001b[49m\u001b[43m(\u001b[49m\n\u001b[1;32m    800\u001b[0m \u001b[43m    \u001b[49m\u001b[43mmethod\u001b[49m\u001b[43m,\u001b[49m\u001b[43m \u001b[49m\u001b[43murl\u001b[49m\u001b[43m,\u001b[49m\u001b[43m \u001b[49m\u001b[43merror\u001b[49m\u001b[38;5;241;43m=\u001b[39;49m\u001b[43me\u001b[49m\u001b[43m,\u001b[49m\u001b[43m \u001b[49m\u001b[43m_pool\u001b[49m\u001b[38;5;241;43m=\u001b[39;49m\u001b[38;5;28;43mself\u001b[39;49m\u001b[43m,\u001b[49m\u001b[43m \u001b[49m\u001b[43m_stacktrace\u001b[49m\u001b[38;5;241;43m=\u001b[39;49m\u001b[43msys\u001b[49m\u001b[38;5;241;43m.\u001b[39;49m\u001b[43mexc_info\u001b[49m\u001b[43m(\u001b[49m\u001b[43m)\u001b[49m\u001b[43m[\u001b[49m\u001b[38;5;241;43m2\u001b[39;49m\u001b[43m]\u001b[49m\n\u001b[1;32m    801\u001b[0m \u001b[43m\u001b[49m\u001b[43m)\u001b[49m\n\u001b[1;32m    802\u001b[0m retries\u001b[38;5;241m.\u001b[39msleep()\n",
      "File \u001b[0;32m~/.local/lib/python3.10/site-packages/urllib3/util/retry.py:592\u001b[0m, in \u001b[0;36mRetry.increment\u001b[0;34m(self, method, url, response, error, _pool, _stacktrace)\u001b[0m\n\u001b[1;32m    591\u001b[0m \u001b[38;5;28;01mif\u001b[39;00m new_retry\u001b[38;5;241m.\u001b[39mis_exhausted():\n\u001b[0;32m--> 592\u001b[0m     \u001b[38;5;28;01mraise\u001b[39;00m MaxRetryError(_pool, url, error \u001b[38;5;129;01mor\u001b[39;00m ResponseError(cause))\n\u001b[1;32m    594\u001b[0m log\u001b[38;5;241m.\u001b[39mdebug(\u001b[38;5;124m\"\u001b[39m\u001b[38;5;124mIncremented Retry for (url=\u001b[39m\u001b[38;5;124m'\u001b[39m\u001b[38;5;132;01m%s\u001b[39;00m\u001b[38;5;124m'\u001b[39m\u001b[38;5;124m): \u001b[39m\u001b[38;5;132;01m%r\u001b[39;00m\u001b[38;5;124m\"\u001b[39m, url, new_retry)\n",
      "\u001b[0;31mMaxRetryError\u001b[0m: HTTPSConnectionPool(host='oaidalleapiprodscus.blob.core.windows.net', port=443): Max retries exceeded with url: /private/org-57DHbubaUsKcpEwBCHTVrS6b/user-ZPTxrE5Z3of20YjzdGT5LsFj/img-o033QAHHhK7D76McIhX05Dnt.png?st=2024-01-10T19%3A43%3A20Z&se=2024-01-10T21%3A43%3A20Z&sp=r&sv=2021-08-06&sr=b&rscd=inline&rsct=image/png&skoid=6aaadede-4fb3-4698-a8f6-684d7786b067&sktid=a48cca56-e6da-484e-a814-9c849652bcb3&skt=2024-01-10T02%3A17%3A20Z&ske=2024-01-11T02%3A17%3A20Z&sks=b&skv=2021-08-06&sig=OUcmsOQD6SYt7pODd8BisWcyTNVd4hRgKNZ/2kvgaMg%3D (Caused by NewConnectionError('<urllib3.connection.HTTPSConnection object at 0x7fd02ff4b790>: Failed to establish a new connection: [Errno -2] Name or service not known'))",
      "\nDuring handling of the above exception, another exception occurred:\n",
      "\u001b[0;31mConnectionError\u001b[0m                           Traceback (most recent call last)",
      "Cell \u001b[0;32mIn[4], line 10\u001b[0m\n\u001b[1;32m      5\u001b[0m headers \u001b[38;5;241m=\u001b[39m {\n\u001b[1;32m      6\u001b[0m     \u001b[38;5;124m\"\u001b[39m\u001b[38;5;124mAuthorization\u001b[39m\u001b[38;5;124m\"\u001b[39m: \u001b[38;5;124mf\u001b[39m\u001b[38;5;124m\"\u001b[39m\u001b[38;5;124mClient-ID \u001b[39m\u001b[38;5;132;01m{\u001b[39;00mapi_key\u001b[38;5;132;01m}\u001b[39;00m\u001b[38;5;124m\"\u001b[39m\n\u001b[1;32m      7\u001b[0m }\n\u001b[1;32m      9\u001b[0m \u001b[38;5;66;03m# Load the generated certificate background image\u001b[39;00m\n\u001b[0;32m---> 10\u001b[0m response \u001b[38;5;241m=\u001b[39m \u001b[43mrequests\u001b[49m\u001b[38;5;241;43m.\u001b[39;49m\u001b[43mget\u001b[49m\u001b[43m(\u001b[49m\u001b[43mimage_url\u001b[49m\u001b[43m)\u001b[49m\n\u001b[1;32m     11\u001b[0m arr \u001b[38;5;241m=\u001b[39m np\u001b[38;5;241m.\u001b[39masarray(\u001b[38;5;28mbytearray\u001b[39m(response\u001b[38;5;241m.\u001b[39mcontent), dtype\u001b[38;5;241m=\u001b[39mnp\u001b[38;5;241m.\u001b[39muint8)\n\u001b[1;32m     12\u001b[0m certificate_background \u001b[38;5;241m=\u001b[39m cv2\u001b[38;5;241m.\u001b[39mimdecode(arr, cv2\u001b[38;5;241m.\u001b[39mIMREAD_COLOR)\n",
      "File \u001b[0;32m~/.local/lib/python3.10/site-packages/requests/api.py:73\u001b[0m, in \u001b[0;36mget\u001b[0;34m(url, params, **kwargs)\u001b[0m\n\u001b[1;32m     62\u001b[0m \u001b[38;5;28;01mdef\u001b[39;00m \u001b[38;5;21mget\u001b[39m(url, params\u001b[38;5;241m=\u001b[39m\u001b[38;5;28;01mNone\u001b[39;00m, \u001b[38;5;241m*\u001b[39m\u001b[38;5;241m*\u001b[39mkwargs):\n\u001b[1;32m     63\u001b[0m \u001b[38;5;250m    \u001b[39m\u001b[38;5;124mr\u001b[39m\u001b[38;5;124;03m\"\"\"Sends a GET request.\u001b[39;00m\n\u001b[1;32m     64\u001b[0m \n\u001b[1;32m     65\u001b[0m \u001b[38;5;124;03m    :param url: URL for the new :class:`Request` object.\u001b[39;00m\n\u001b[0;32m   (...)\u001b[0m\n\u001b[1;32m     70\u001b[0m \u001b[38;5;124;03m    :rtype: requests.Response\u001b[39;00m\n\u001b[1;32m     71\u001b[0m \u001b[38;5;124;03m    \"\"\"\u001b[39;00m\n\u001b[0;32m---> 73\u001b[0m     \u001b[38;5;28;01mreturn\u001b[39;00m \u001b[43mrequest\u001b[49m\u001b[43m(\u001b[49m\u001b[38;5;124;43m\"\u001b[39;49m\u001b[38;5;124;43mget\u001b[39;49m\u001b[38;5;124;43m\"\u001b[39;49m\u001b[43m,\u001b[49m\u001b[43m \u001b[49m\u001b[43murl\u001b[49m\u001b[43m,\u001b[49m\u001b[43m \u001b[49m\u001b[43mparams\u001b[49m\u001b[38;5;241;43m=\u001b[39;49m\u001b[43mparams\u001b[49m\u001b[43m,\u001b[49m\u001b[43m \u001b[49m\u001b[38;5;241;43m*\u001b[39;49m\u001b[38;5;241;43m*\u001b[39;49m\u001b[43mkwargs\u001b[49m\u001b[43m)\u001b[49m\n",
      "File \u001b[0;32m~/.local/lib/python3.10/site-packages/requests/api.py:59\u001b[0m, in \u001b[0;36mrequest\u001b[0;34m(method, url, **kwargs)\u001b[0m\n\u001b[1;32m     55\u001b[0m \u001b[38;5;66;03m# By using the 'with' statement we are sure the session is closed, thus we\u001b[39;00m\n\u001b[1;32m     56\u001b[0m \u001b[38;5;66;03m# avoid leaving sockets open which can trigger a ResourceWarning in some\u001b[39;00m\n\u001b[1;32m     57\u001b[0m \u001b[38;5;66;03m# cases, and look like a memory leak in others.\u001b[39;00m\n\u001b[1;32m     58\u001b[0m \u001b[38;5;28;01mwith\u001b[39;00m sessions\u001b[38;5;241m.\u001b[39mSession() \u001b[38;5;28;01mas\u001b[39;00m session:\n\u001b[0;32m---> 59\u001b[0m     \u001b[38;5;28;01mreturn\u001b[39;00m \u001b[43msession\u001b[49m\u001b[38;5;241;43m.\u001b[39;49m\u001b[43mrequest\u001b[49m\u001b[43m(\u001b[49m\u001b[43mmethod\u001b[49m\u001b[38;5;241;43m=\u001b[39;49m\u001b[43mmethod\u001b[49m\u001b[43m,\u001b[49m\u001b[43m \u001b[49m\u001b[43murl\u001b[49m\u001b[38;5;241;43m=\u001b[39;49m\u001b[43murl\u001b[49m\u001b[43m,\u001b[49m\u001b[43m \u001b[49m\u001b[38;5;241;43m*\u001b[39;49m\u001b[38;5;241;43m*\u001b[39;49m\u001b[43mkwargs\u001b[49m\u001b[43m)\u001b[49m\n",
      "File \u001b[0;32m~/.local/lib/python3.10/site-packages/requests/sessions.py:589\u001b[0m, in \u001b[0;36mSession.request\u001b[0;34m(self, method, url, params, data, headers, cookies, files, auth, timeout, allow_redirects, proxies, hooks, stream, verify, cert, json)\u001b[0m\n\u001b[1;32m    584\u001b[0m send_kwargs \u001b[38;5;241m=\u001b[39m {\n\u001b[1;32m    585\u001b[0m     \u001b[38;5;124m\"\u001b[39m\u001b[38;5;124mtimeout\u001b[39m\u001b[38;5;124m\"\u001b[39m: timeout,\n\u001b[1;32m    586\u001b[0m     \u001b[38;5;124m\"\u001b[39m\u001b[38;5;124mallow_redirects\u001b[39m\u001b[38;5;124m\"\u001b[39m: allow_redirects,\n\u001b[1;32m    587\u001b[0m }\n\u001b[1;32m    588\u001b[0m send_kwargs\u001b[38;5;241m.\u001b[39mupdate(settings)\n\u001b[0;32m--> 589\u001b[0m resp \u001b[38;5;241m=\u001b[39m \u001b[38;5;28;43mself\u001b[39;49m\u001b[38;5;241;43m.\u001b[39;49m\u001b[43msend\u001b[49m\u001b[43m(\u001b[49m\u001b[43mprep\u001b[49m\u001b[43m,\u001b[49m\u001b[43m \u001b[49m\u001b[38;5;241;43m*\u001b[39;49m\u001b[38;5;241;43m*\u001b[39;49m\u001b[43msend_kwargs\u001b[49m\u001b[43m)\u001b[49m\n\u001b[1;32m    591\u001b[0m \u001b[38;5;28;01mreturn\u001b[39;00m resp\n",
      "File \u001b[0;32m~/.local/lib/python3.10/site-packages/requests/sessions.py:703\u001b[0m, in \u001b[0;36mSession.send\u001b[0;34m(self, request, **kwargs)\u001b[0m\n\u001b[1;32m    700\u001b[0m start \u001b[38;5;241m=\u001b[39m preferred_clock()\n\u001b[1;32m    702\u001b[0m \u001b[38;5;66;03m# Send the request\u001b[39;00m\n\u001b[0;32m--> 703\u001b[0m r \u001b[38;5;241m=\u001b[39m \u001b[43madapter\u001b[49m\u001b[38;5;241;43m.\u001b[39;49m\u001b[43msend\u001b[49m\u001b[43m(\u001b[49m\u001b[43mrequest\u001b[49m\u001b[43m,\u001b[49m\u001b[43m \u001b[49m\u001b[38;5;241;43m*\u001b[39;49m\u001b[38;5;241;43m*\u001b[39;49m\u001b[43mkwargs\u001b[49m\u001b[43m)\u001b[49m\n\u001b[1;32m    705\u001b[0m \u001b[38;5;66;03m# Total elapsed time of the request (approximately)\u001b[39;00m\n\u001b[1;32m    706\u001b[0m elapsed \u001b[38;5;241m=\u001b[39m preferred_clock() \u001b[38;5;241m-\u001b[39m start\n",
      "File \u001b[0;32m~/.local/lib/python3.10/site-packages/requests/adapters.py:519\u001b[0m, in \u001b[0;36mHTTPAdapter.send\u001b[0;34m(self, request, stream, timeout, verify, cert, proxies)\u001b[0m\n\u001b[1;32m    515\u001b[0m     \u001b[38;5;28;01mif\u001b[39;00m \u001b[38;5;28misinstance\u001b[39m(e\u001b[38;5;241m.\u001b[39mreason, _SSLError):\n\u001b[1;32m    516\u001b[0m         \u001b[38;5;66;03m# This branch is for urllib3 v1.22 and later.\u001b[39;00m\n\u001b[1;32m    517\u001b[0m         \u001b[38;5;28;01mraise\u001b[39;00m SSLError(e, request\u001b[38;5;241m=\u001b[39mrequest)\n\u001b[0;32m--> 519\u001b[0m     \u001b[38;5;28;01mraise\u001b[39;00m \u001b[38;5;167;01mConnectionError\u001b[39;00m(e, request\u001b[38;5;241m=\u001b[39mrequest)\n\u001b[1;32m    521\u001b[0m \u001b[38;5;28;01mexcept\u001b[39;00m ClosedPoolError \u001b[38;5;28;01mas\u001b[39;00m e:\n\u001b[1;32m    522\u001b[0m     \u001b[38;5;28;01mraise\u001b[39;00m \u001b[38;5;167;01mConnectionError\u001b[39;00m(e, request\u001b[38;5;241m=\u001b[39mrequest)\n",
      "\u001b[0;31mConnectionError\u001b[0m: HTTPSConnectionPool(host='oaidalleapiprodscus.blob.core.windows.net', port=443): Max retries exceeded with url: /private/org-57DHbubaUsKcpEwBCHTVrS6b/user-ZPTxrE5Z3of20YjzdGT5LsFj/img-o033QAHHhK7D76McIhX05Dnt.png?st=2024-01-10T19%3A43%3A20Z&se=2024-01-10T21%3A43%3A20Z&sp=r&sv=2021-08-06&sr=b&rscd=inline&rsct=image/png&skoid=6aaadede-4fb3-4698-a8f6-684d7786b067&sktid=a48cca56-e6da-484e-a814-9c849652bcb3&skt=2024-01-10T02%3A17%3A20Z&ske=2024-01-11T02%3A17%3A20Z&sks=b&skv=2021-08-06&sig=OUcmsOQD6SYt7pODd8BisWcyTNVd4hRgKNZ/2kvgaMg%3D (Caused by NewConnectionError('<urllib3.connection.HTTPSConnection object at 0x7fd02ff4b790>: Failed to establish a new connection: [Errno -2] Name or service not known'))"
     ]
    }
   ],
   "source": [
    "import cv2\n",
    "import requests\n",
    "import numpy as np\n",
    "\n",
    "headers = {\n",
    "    \"Authorization\": f\"Client-ID {api_key}\"\n",
    "}\n",
    "\n",
    "# Load the generated certificate background image\n",
    "response = requests.get(image_url)\n",
    "arr = np.asarray(bytearray(response.content), dtype=np.uint8)\n",
    "certificate_background = cv2.imdecode(arr, cv2.IMREAD_COLOR)\n",
    "\n",
    "# Load the logo image\n",
    "url = \"https://api.imgur.com/3/upload\"\n",
    "file_path = \"/home/hp/Documents/week 5/new/End-to-End-web3-dapps-certifcate-generation/image_generation/logo.png\"\n",
    "with open(file_path, 'rb') as file:\n",
    "    response = requests.post(url, files={'file': file})\n",
    "arr = np.asarray(bytearray(response.content), dtype=np.uint8)\n",
    "logo_image = cv2.imdecode(arr, cv2.IMREAD_COLOR)\n",
    "\n",
    "# Prepare the text and information for the certificate\n",
    "full_name = \"ten academician\"\n",
    "date = \"January 10, 2024\"\n",
    "other_info = \"Great distinction\"\n",
    "\n",
    "# Load the font\n",
    "font_path = \"/usr/share/fonts/truetype/dejavu/DejaVuSans.ttf\"\n",
    "font_size = 48\n",
    "font = cv2.FONT_HERSHEY_SIMPLEX\n",
    "\n",
    "# Create a blank certificate image with the same size as the background\n",
    "certificate = np.copy(certificate_background)\n",
    "\n",
    "# Paste the logo image onto the certificate\n",
    "x, y = 100, 100\n",
    "certificate[y:y + logo_image.shape[0], x:x + logo_image.shape[1]] = logo_image\n",
    "\n",
    "# Draw the text onto the certificate image\n",
    "text_position = (100, 400)\n",
    "text_color = (0, 0, 0)\n",
    "text_thickness = 2\n",
    "text_line_type = cv2.LINE_AA\n",
    "\n",
    "cv2.putText(certificate, full_name, text_position, font, font_size, text_color, text_thickness, text_line_type)\n",
    "cv2.putText(certificate, date, (text_position[0], text_position[1] + 60), font, font_size, text_color, text_thickness, text_line_type)\n",
    "cv2.putText(certificate, other_info, (text_position[0], text_position[1] + 120), font, font_size, text_color, text_thickness, text_line_type)\n",
    "\n",
    "# Save the final certificate image\n",
    "cv2.imwrite(\"certificate.png\", certificate)"
   ]
  }
 ],
 "metadata": {
  "kernelspec": {
   "display_name": "Python 3",
   "language": "python",
   "name": "python3"
  },
  "language_info": {
   "codemirror_mode": {
    "name": "ipython",
    "version": 3
   },
   "file_extension": ".py",
   "mimetype": "text/x-python",
   "name": "python",
   "nbconvert_exporter": "python",
   "pygments_lexer": "ipython3",
   "version": "3.10.12"
  }
 },
 "nbformat": 4,
 "nbformat_minor": 2
}
